[19/Jul/2020 07:02:30] "GET / HTTP/1.1" 200 14935
[19/Jul/2020 07:02:31] "GET / HTTP/1.1" 200 14935
[19/Jul/2020 07:02:37] "GET / HTTP/1.1" 200 14935
[19/Jul/2020 07:02:38] "GET / HTTP/1.1" 200 14935
[19/Jul/2020 07:02:38] "GET / HTTP/1.1" 200 14935
[19/Jul/2020 07:02:38] "GET / HTTP/1.1" 200 14935
[19/Jul/2020 07:02:38] "GET / HTTP/1.1" 200 14935
[19/Jul/2020 07:02:48] "GET / HTTP/1.1" 200 14935
[19/Jul/2020 07:02:50] "GET /login/ HTTP/1.1" 200 2152
[19/Jul/2020 07:02:50] "GET /static/css/accounts.css HTTP/1.1" 200 201
[19/Jul/2020 07:02:50] "GET /static/css/img/circle-blues.png HTTP/1.1" 404 179
[19/Jul/2020 07:02:58] "POST /login/ HTTP/1.1" 200 2359
[19/Jul/2020 07:02:58] "GET /static/css/img/circle-blues.png HTTP/1.1" 404 179
[19/Jul/2020 07:03:09] "POST /login/ HTTP/1.1" 200 2366
[19/Jul/2020 07:03:09] "GET /static/css/img/circle-blues.png HTTP/1.1" 404 179
[19/Jul/2020 07:03:17] "POST /login/ HTTP/1.1" 200 2366
[19/Jul/2020 07:03:42] "POST /login/ HTTP/1.1" 200 2366
[19/Jul/2020 07:03:50] "POST /login/ HTTP/1.1" 200 2359
[19/Jul/2020 07:03:53] "GET /signup/ HTTP/1.1" 200 3015
[19/Jul/2020 07:04:12] "POST /signup/ HTTP/1.1" 200 3194
[19/Jul/2020 07:04:23] "GET /login/ HTTP/1.1" 200 2152
[19/Jul/2020 07:04:32] "POST /login/ HTTP/1.1" 200 2359
[19/Jul/2020 07:04:38] "POST /login/ HTTP/1.1" 302 0
[19/Jul/2020 07:04:39] "GET / HTTP/1.1" 200 15378
[19/Jul/2020 07:09:11] "GET / HTTP/1.1" 200 15378
[19/Jul/2020 07:09:12] "GET / HTTP/1.1" 200 15378
[19/Jul/2020 07:09:12] "GET / HTTP/1.1" 200 15378
[19/Jul/2020 07:09:12] "GET / HTTP/1.1" 200 15378
[19/Jul/2020 07:09:41] "GET / HTTP/1.1" 200 14935
[19/Jul/2020 07:09:42] "GET /static/css/app.css HTTP/1.1" 200 54
[19/Jul/2020 07:09:42] "GET /static/js/popper.min.js HTTP/1.1" 200 21257
[19/Jul/2020 07:09:42] "GET /static/js/jquery-3.4.1.min.js HTTP/1.1" 200 88145
[19/Jul/2020 07:09:44] "GET /static/css/bootstrap.css HTTP/1.1" 200 178159
[19/Jul/2020 07:09:44] "GET /static/js/bootstrap.js HTTP/1.1" 200 136323
[19/Jul/2020 07:09:45] "GET /favicon.ico HTTP/1.1" 404 179
[19/Jul/2020 07:10:25] "GET /login/ HTTP/1.1" 200 2152
[19/Jul/2020 07:10:26] "GET /static/css/accounts.css HTTP/1.1" 200 201
[19/Jul/2020 07:10:27] "GET /static/css/img/circle-blues.png HTTP/1.1" 404 179
[19/Jul/2020 07:10:28] "GET /favicon.ico HTTP/1.1" 404 179
[19/Jul/2020 07:10:29] "GET /signup/ HTTP/1.1" 200 3015
[19/Jul/2020 07:10:30] "GET /favicon.ico HTTP/1.1" 404 179
[19/Jul/2020 07:11:29] "POST /signup/ HTTP/1.1" 302 0
[19/Jul/2020 07:11:30] "GET / HTTP/1.1" 200 15385
[19/Jul/2020 07:11:30] "GET /favicon.ico HTTP/1.1" 404 179
[19/Jul/2020 07:11:50] "GET /reset/ HTTP/1.1" 200 1708
[19/Jul/2020 07:11:50] "GET /favicon.ico HTTP/1.1" 404 179
[19/Jul/2020 07:11:55] "GET /logout/ HTTP/1.1" 302 0
[19/Jul/2020 07:11:56] "GET / HTTP/1.1" 200 14935
[19/Jul/2020 07:11:56] "GET /favicon.ico HTTP/1.1" 404 179
[19/Jul/2020 07:24:21] "GET / HTTP/1.1" 200 15378
[19/Jul/2020 07:40:46] "GET / HTTP/1.1" 200 15378
[19/Jul/2020 08:00:32] "GET http://www.baidu.com/cache/global/img/gs.gif HTTP/1.1" 404 179
----------------------------------------
Exception happened during processing of request from ('80.82.70.187', 44774)
Traceback (most recent call last):
  File "/home/hzl/anaconda3/envs/django_web/lib/python3.8/socketserver.py", line 650, in process_request_thread
    self.finish_request(request, client_address)
  File "/home/hzl/anaconda3/envs/django_web/lib/python3.8/socketserver.py", line 360, in finish_request
    self.RequestHandlerClass(request, client_address, self)
  File "/home/hzl/anaconda3/envs/django_web/lib/python3.8/socketserver.py", line 720, in __init__
    self.handle()
  File "/home/hzl/anaconda3/envs/django_web/lib/python3.8/site-packages/django/core/servers/basehttp.py", line 174, in handle
    self.handle_one_request()
  File "/home/hzl/anaconda3/envs/django_web/lib/python3.8/site-packages/django/core/servers/basehttp.py", line 182, in handle_one_request
    self.raw_requestline = self.rfile.readline(65537)
  File "/home/hzl/anaconda3/envs/django_web/lib/python3.8/socket.py", line 669, in readinto
    return self._sock.recv_into(b)
ConnectionResetError: [Errno 104] Connection reset by peer
----------------------------------------
Performing system checks...

System check identified no issues (0 silenced).
July 19, 2020 - 07:02:18
Django version 3.0.3, using settings 'myproject.settings'
Starting development server at http://0.0.0.0:8000/
Quit the server with CONTROL-C.
Exception in thread django-main-thread:
Traceback (most recent call last):
  File "/home/hzl/anaconda3/envs/django_web/lib/python3.8/threading.py", line 932, in _bootstrap_inner
    self.run()
  File "/home/hzl/anaconda3/envs/django_web/lib/python3.8/threading.py", line 870, in run
    self._target(*self._args, **self._kwargs)
  File "/home/hzl/anaconda3/envs/django_web/lib/python3.8/site-packages/django/utils/autoreload.py", line 53, in wrapper
    fn(*args, **kwargs)
  File "/home/hzl/anaconda3/envs/django_web/lib/python3.8/site-packages/django/core/management/commands/runserver.py", line 117, in inner_run
    self.check(display_num_errors=True)
  File "/home/hzl/anaconda3/envs/django_web/lib/python3.8/site-packages/django/core/management/base.py", line 392, in check
    all_issues = self._run_checks(
  File "/home/hzl/anaconda3/envs/django_web/lib/python3.8/site-packages/django/core/management/base.py", line 382, in _run_checks
    return checks.run_checks(**kwargs)
  File "/home/hzl/anaconda3/envs/django_web/lib/python3.8/site-packages/django/core/checks/registry.py", line 72, in run_checks
    new_errors = check(app_configs=app_configs)
  File "/home/hzl/anaconda3/envs/django_web/lib/python3.8/site-packages/django/core/checks/urls.py", line 13, in check_url_config
    return check_resolver(resolver)
  File "/home/hzl/anaconda3/envs/django_web/lib/python3.8/site-packages/django/core/checks/urls.py", line 23, in check_resolver
    return check_method()
  File "/home/hzl/anaconda3/envs/django_web/lib/python3.8/site-packages/django/urls/resolvers.py", line 407, in check
    for pattern in self.url_patterns:
  File "/home/hzl/anaconda3/envs/django_web/lib/python3.8/site-packages/django/utils/functional.py", line 48, in __get__
    res = instance.__dict__[self.name] = self.func(instance)
  File "/home/hzl/anaconda3/envs/django_web/lib/python3.8/site-packages/django/urls/resolvers.py", line 588, in url_patterns
    patterns = getattr(self.urlconf_module, "urlpatterns", self.urlconf_module)
  File "/home/hzl/anaconda3/envs/django_web/lib/python3.8/site-packages/django/utils/functional.py", line 48, in __get__
    res = instance.__dict__[self.name] = self.func(instance)
  File "/home/hzl/anaconda3/envs/django_web/lib/python3.8/site-packages/django/urls/resolvers.py", line 581, in urlconf_module
    return import_module(self.urlconf_name)
  File "/home/hzl/anaconda3/envs/django_web/lib/python3.8/importlib/__init__.py", line 127, in import_module
    return _bootstrap._gcd_import(name[level:], package, level)
  File "<frozen importlib._bootstrap>", line 1014, in _gcd_import
  File "<frozen importlib._bootstrap>", line 991, in _find_and_load
  File "<frozen importlib._bootstrap>", line 975, in _find_and_load_unlocked
  File "<frozen importlib._bootstrap>", line 671, in _load_unlocked
  File "<frozen importlib._bootstrap_external>", line 783, in exec_module
  File "<frozen importlib._bootstrap>", line 219, in _call_with_frames_removed
  File "/home/hzl/django_web/myproject/myproject/urls.py", line 33, in <module>
    url(r'^blog$',views.createblog,name='creatblog'),
AttributeError: module 'boards.views' has no attribute 'createblog'
Performing system checks...

Exception in thread django-main-thread:
Traceback (most recent call last):
  File "/home/hzl/anaconda3/envs/django_web/lib/python3.8/threading.py", line 932, in _bootstrap_inner
    self.run()
  File "/home/hzl/anaconda3/envs/django_web/lib/python3.8/threading.py", line 870, in run
    self._target(*self._args, **self._kwargs)
  File "/home/hzl/anaconda3/envs/django_web/lib/python3.8/site-packages/django/utils/autoreload.py", line 53, in wrapper
    fn(*args, **kwargs)
  File "/home/hzl/anaconda3/envs/django_web/lib/python3.8/site-packages/django/core/management/commands/runserver.py", line 117, in inner_run
    self.check(display_num_errors=True)
  File "/home/hzl/anaconda3/envs/django_web/lib/python3.8/site-packages/django/core/management/base.py", line 392, in check
    all_issues = self._run_checks(
  File "/home/hzl/anaconda3/envs/django_web/lib/python3.8/site-packages/django/core/management/base.py", line 382, in _run_checks
    return checks.run_checks(**kwargs)
  File "/home/hzl/anaconda3/envs/django_web/lib/python3.8/site-packages/django/core/checks/registry.py", line 72, in run_checks
    new_errors = check(app_configs=app_configs)
  File "/home/hzl/anaconda3/envs/django_web/lib/python3.8/site-packages/django/core/checks/urls.py", line 13, in check_url_config
    return check_resolver(resolver)
  File "/home/hzl/anaconda3/envs/django_web/lib/python3.8/site-packages/django/core/checks/urls.py", line 23, in check_resolver
    return check_method()
  File "/home/hzl/anaconda3/envs/django_web/lib/python3.8/site-packages/django/urls/resolvers.py", line 407, in check
    for pattern in self.url_patterns:
  File "/home/hzl/anaconda3/envs/django_web/lib/python3.8/site-packages/django/utils/functional.py", line 48, in __get__
    res = instance.__dict__[self.name] = self.func(instance)
  File "/home/hzl/anaconda3/envs/django_web/lib/python3.8/site-packages/django/urls/resolvers.py", line 588, in url_patterns
    patterns = getattr(self.urlconf_module, "urlpatterns", self.urlconf_module)
  File "/home/hzl/anaconda3/envs/django_web/lib/python3.8/site-packages/django/utils/functional.py", line 48, in __get__
    res = instance.__dict__[self.name] = self.func(instance)
  File "/home/hzl/anaconda3/envs/django_web/lib/python3.8/site-packages/django/urls/resolvers.py", line 581, in urlconf_module
    return import_module(self.urlconf_name)
  File "/home/hzl/anaconda3/envs/django_web/lib/python3.8/importlib/__init__.py", line 127, in import_module
    return _bootstrap._gcd_import(name[level:], package, level)
  File "<frozen importlib._bootstrap>", line 1014, in _gcd_import
  File "<frozen importlib._bootstrap>", line 991, in _find_and_load
  File "<frozen importlib._bootstrap>", line 975, in _find_and_load_unlocked
  File "<frozen importlib._bootstrap>", line 671, in _load_unlocked
  File "<frozen importlib._bootstrap_external>", line 783, in exec_module
  File "<frozen importlib._bootstrap>", line 219, in _call_with_frames_removed
  File "/home/hzl/django_web/myproject/myproject/urls.py", line 33, in <module>
    url(r'^blog$',views.createblog,name='createblog'),
AttributeError: module 'boards.views' has no attribute 'createblog'
Performing system checks...

Exception in thread django-main-thread:
Traceback (most recent call last):
  File "/home/hzl/anaconda3/envs/django_web/lib/python3.8/threading.py", line 932, in _bootstrap_inner
    self.run()
  File "/home/hzl/anaconda3/envs/django_web/lib/python3.8/threading.py", line 870, in run
    self._target(*self._args, **self._kwargs)
  File "/home/hzl/anaconda3/envs/django_web/lib/python3.8/site-packages/django/utils/autoreload.py", line 53, in wrapper
    fn(*args, **kwargs)
  File "/home/hzl/anaconda3/envs/django_web/lib/python3.8/site-packages/django/core/management/commands/runserver.py", line 117, in inner_run
    self.check(display_num_errors=True)
  File "/home/hzl/anaconda3/envs/django_web/lib/python3.8/site-packages/django/core/management/base.py", line 392, in check
    all_issues = self._run_checks(
  File "/home/hzl/anaconda3/envs/django_web/lib/python3.8/site-packages/django/core/management/base.py", line 382, in _run_checks
    return checks.run_checks(**kwargs)
  File "/home/hzl/anaconda3/envs/django_web/lib/python3.8/site-packages/django/core/checks/registry.py", line 72, in run_checks
    new_errors = check(app_configs=app_configs)
  File "/home/hzl/anaconda3/envs/django_web/lib/python3.8/site-packages/django/core/checks/urls.py", line 13, in check_url_config
    return check_resolver(resolver)
  File "/home/hzl/anaconda3/envs/django_web/lib/python3.8/site-packages/django/core/checks/urls.py", line 23, in check_resolver
    return check_method()
  File "/home/hzl/anaconda3/envs/django_web/lib/python3.8/site-packages/django/urls/resolvers.py", line 407, in check
    for pattern in self.url_patterns:
  File "/home/hzl/anaconda3/envs/django_web/lib/python3.8/site-packages/django/utils/functional.py", line 48, in __get__
    res = instance.__dict__[self.name] = self.func(instance)
  File "/home/hzl/anaconda3/envs/django_web/lib/python3.8/site-packages/django/urls/resolvers.py", line 588, in url_patterns
    patterns = getattr(self.urlconf_module, "urlpatterns", self.urlconf_module)
  File "/home/hzl/anaconda3/envs/django_web/lib/python3.8/site-packages/django/utils/functional.py", line 48, in __get__
    res = instance.__dict__[self.name] = self.func(instance)
  File "/home/hzl/anaconda3/envs/django_web/lib/python3.8/site-packages/django/urls/resolvers.py", line 581, in urlconf_module
    return import_module(self.urlconf_name)
  File "/home/hzl/anaconda3/envs/django_web/lib/python3.8/importlib/__init__.py", line 127, in import_module
    return _bootstrap._gcd_import(name[level:], package, level)
  File "<frozen importlib._bootstrap>", line 1014, in _gcd_import
  File "<frozen importlib._bootstrap>", line 991, in _find_and_load
  File "<frozen importlib._bootstrap>", line 975, in _find_and_load_unlocked
  File "<frozen importlib._bootstrap>", line 671, in _load_unlocked
  File "<frozen importlib._bootstrap_external>", line 783, in exec_module
  File "<frozen importlib._bootstrap>", line 219, in _call_with_frames_removed
  File "/home/hzl/django_web/myproject/myproject/urls.py", line 33, in <module>
    url(r'^blog$',views.createblog,name='createblog'),
AttributeError: module 'boards.views' has no attribute 'createblog'
Performing system checks...

Performing system checks...

System check identified no issues (0 silenced).
July 19, 2020 - 08:21:47
Django version 3.0.3, using settings 'myproject.settings'
Starting development server at http://0.0.0.0:8000/
Quit the server with CONTROL-C.
[19/Jul/2020 08:24:05] "GET / HTTP/1.1" 200 15378
[19/Jul/2020 08:24:06] "GET / HTTP/1.1" 200 15378
[19/Jul/2020 08:24:06] "GET / HTTP/1.1" 200 15378
[19/Jul/2020 08:24:06] "GET / HTTP/1.1" 200 15378
[19/Jul/2020 08:24:07] "GET / HTTP/1.1" 200 15378
[19/Jul/2020 08:24:07] "GET / HTTP/1.1" 200 15378
[19/Jul/2020 08:24:07] "GET / HTTP/1.1" 200 15378
[19/Jul/2020 08:24:09] "GET / HTTP/1.1" 200 15378
[19/Jul/2020 08:24:11] "GET / HTTP/1.1" 200 15378
[19/Jul/2020 08:24:11] "GET / HTTP/1.1" 200 15378
Performing system checks...

System check identified no issues (0 silenced).
July 19, 2020 - 08:24:03
Django version 3.0.3, using settings 'myproject.settings'
Starting development server at http://0.0.0.0:8000/
Quit the server with CONTROL-C.
Performing system checks...

System check identified no issues (0 silenced).
July 19, 2020 - 08:53:30
Django version 3.0.3, using settings 'myproject.settings'
Starting development server at http://0.0.0.0:8000/
Quit the server with CONTROL-C.
[19/Jul/2020 08:54:29] "GET /blog HTTP/1.1" 200 4144
[19/Jul/2020 08:54:31] "GET / HTTP/1.1" 200 15382
[19/Jul/2020 08:54:32] "GET /blog HTTP/1.1" 200 4144
[19/Jul/2020 08:54:33] "GET / HTTP/1.1" 200 15382
[19/Jul/2020 08:54:39] "GET /logout/ HTTP/1.1" 302 0
[19/Jul/2020 08:54:39] "GET / HTTP/1.1" 200 14939
[19/Jul/2020 08:54:42] "GET / HTTP/1.1" 200 14939
[19/Jul/2020 08:54:45] "GET /blog HTTP/1.1" 200 3701
[19/Jul/2020 08:54:59] "GET /blog HTTP/1.1" 200 3701
[19/Jul/2020 08:55:00] "GET /blog HTTP/1.1" 200 3701
[19/Jul/2020 08:55:02] "GET / HTTP/1.1" 200 14939
[19/Jul/2020 08:55:03] "GET / HTTP/1.1" 200 14939
[19/Jul/2020 08:55:03] "GET /blog HTTP/1.1" 200 3701
[19/Jul/2020 08:55:55] "GET /blog HTTP/1.1" 200 3701
[19/Jul/2020 08:55:56] "GET /blog HTTP/1.1" 200 3701
[19/Jul/2020 08:55:58] "GET / HTTP/1.1" 200 14939
[19/Jul/2020 08:55:59] "GET / HTTP/1.1" 200 14939
[19/Jul/2020 08:56:00] "GET /blog HTTP/1.1" 200 3701
Performing system checks...

System check identified no issues (0 silenced).
July 19, 2020 - 08:54:16
Django version 3.0.3, using settings 'myproject.settings'
Starting development server at http://0.0.0.0:8000/
Quit the server with CONTROL-C.
Performing system checks...

System check identified no issues (0 silenced).
July 19, 2020 - 08:57:16
Django version 3.0.3, using settings 'myproject.settings'
Starting development server at http://0.0.0.0:8000/
Quit the server with CONTROL-C.
[19/Jul/2020 08:58:19] "GET /blog HTTP/1.1" 200 4240
[19/Jul/2020 08:58:22] "GET / HTTP/1.1" 200 14939
[19/Jul/2020 08:58:23] "GET /blog HTTP/1.1" 200 4240
[19/Jul/2020 08:58:33] "GET / HTTP/1.1" 200 14939
[19/Jul/2020 08:58:40] "GET /blog HTTP/1.1" 200 4240
[19/Jul/2020 08:59:25] "POST /blog HTTP/1.1" 200 4240
[19/Jul/2020 08:59:29] "GET / HTTP/1.1" 200 14939
[19/Jul/2020 08:59:37] "GET /blog HTTP/1.1" 200 4240
Performing system checks...

System check identified no issues (0 silenced).
July 19, 2020 - 08:58:12
Django version 3.0.3, using settings 'myproject.settings'
Starting development server at http://0.0.0.0:8000/
Quit the server with CONTROL-C.
Exception in thread django-main-thread:
Traceback (most recent call last):
  File "/home/hzl/anaconda3/envs/django_web/lib/python3.8/threading.py", line 932, in _bootstrap_inner
    self.run()
  File "/home/hzl/anaconda3/envs/django_web/lib/python3.8/threading.py", line 870, in run
    self._target(*self._args, **self._kwargs)
  File "/home/hzl/anaconda3/envs/django_web/lib/python3.8/site-packages/django/utils/autoreload.py", line 53, in wrapper
    fn(*args, **kwargs)
  File "/home/hzl/anaconda3/envs/django_web/lib/python3.8/site-packages/django/core/management/commands/runserver.py", line 109, in inner_run
    autoreload.raise_last_exception()
  File "/home/hzl/anaconda3/envs/django_web/lib/python3.8/site-packages/django/utils/autoreload.py", line 76, in raise_last_exception
    raise _exception[1]
  File "/home/hzl/anaconda3/envs/django_web/lib/python3.8/site-packages/django/core/management/__init__.py", line 357, in execute
    autoreload.check_errors(django.setup)()
  File "/home/hzl/anaconda3/envs/django_web/lib/python3.8/site-packages/django/utils/autoreload.py", line 53, in wrapper
    fn(*args, **kwargs)
  File "/home/hzl/anaconda3/envs/django_web/lib/python3.8/site-packages/django/__init__.py", line 24, in setup
    apps.populate(settings.INSTALLED_APPS)
  File "/home/hzl/anaconda3/envs/django_web/lib/python3.8/site-packages/django/apps/registry.py", line 114, in populate
    app_config.import_models()
  File "/home/hzl/anaconda3/envs/django_web/lib/python3.8/site-packages/django/apps/config.py", line 211, in import_models
    self.models_module = import_module(models_module_name)
  File "/home/hzl/anaconda3/envs/django_web/lib/python3.8/importlib/__init__.py", line 127, in import_module
    return _bootstrap._gcd_import(name[level:], package, level)
  File "<frozen importlib._bootstrap>", line 1014, in _gcd_import
  File "<frozen importlib._bootstrap>", line 991, in _find_and_load
  File "<frozen importlib._bootstrap>", line 975, in _find_and_load_unlocked
  File "<frozen importlib._bootstrap>", line 671, in _load_unlocked
  File "<frozen importlib._bootstrap_external>", line 779, in exec_module
  File "<frozen importlib._bootstrap_external>", line 916, in get_code
  File "<frozen importlib._bootstrap_external>", line 846, in source_to_code
  File "<frozen importlib._bootstrap>", line 219, in _call_with_frames_removed
  File "/home/hzl/django_web/myproject/boards/models.py", line 34
    return self.subject
                      ^
TabError: inconsistent use of tabs and spaces in indentation
Exception in thread django-main-thread:
Traceback (most recent call last):
  File "/home/hzl/anaconda3/envs/django_web/lib/python3.8/threading.py", line 932, in _bootstrap_inner
    self.run()
  File "/home/hzl/anaconda3/envs/django_web/lib/python3.8/threading.py", line 870, in run
    self._target(*self._args, **self._kwargs)
  File "/home/hzl/anaconda3/envs/django_web/lib/python3.8/site-packages/django/utils/autoreload.py", line 53, in wrapper
    fn(*args, **kwargs)
  File "/home/hzl/anaconda3/envs/django_web/lib/python3.8/site-packages/django/core/management/commands/runserver.py", line 109, in inner_run
    autoreload.raise_last_exception()
  File "/home/hzl/anaconda3/envs/django_web/lib/python3.8/site-packages/django/utils/autoreload.py", line 76, in raise_last_exception
    raise _exception[1]
  File "/home/hzl/anaconda3/envs/django_web/lib/python3.8/site-packages/django/core/management/__init__.py", line 357, in execute
    autoreload.check_errors(django.setup)()
  File "/home/hzl/anaconda3/envs/django_web/lib/python3.8/site-packages/django/utils/autoreload.py", line 53, in wrapper
    fn(*args, **kwargs)
  File "/home/hzl/anaconda3/envs/django_web/lib/python3.8/site-packages/django/__init__.py", line 24, in setup
    apps.populate(settings.INSTALLED_APPS)
  File "/home/hzl/anaconda3/envs/django_web/lib/python3.8/site-packages/django/apps/registry.py", line 114, in populate
    app_config.import_models()
  File "/home/hzl/anaconda3/envs/django_web/lib/python3.8/site-packages/django/apps/config.py", line 211, in import_models
    self.models_module = import_module(models_module_name)
  File "/home/hzl/anaconda3/envs/django_web/lib/python3.8/importlib/__init__.py", line 127, in import_module
    return _bootstrap._gcd_import(name[level:], package, level)
  File "<frozen importlib._bootstrap>", line 1014, in _gcd_import
  File "<frozen importlib._bootstrap>", line 991, in _find_and_load
  File "<frozen importlib._bootstrap>", line 975, in _find_and_load_unlocked
  File "<frozen importlib._bootstrap>", line 671, in _load_unlocked
  File "<frozen importlib._bootstrap_external>", line 779, in exec_module
  File "<frozen importlib._bootstrap_external>", line 916, in get_code
  File "<frozen importlib._bootstrap_external>", line 846, in source_to_code
  File "<frozen importlib._bootstrap>", line 219, in _call_with_frames_removed
  File "/home/hzl/django_web/myproject/boards/models.py", line 34
    return self.subject
                      ^
TabError: inconsistent use of tabs and spaces in indentation
Exception in thread django-main-thread:
Traceback (most recent call last):
  File "/home/hzl/anaconda3/envs/django_web/lib/python3.8/threading.py", line 932, in _bootstrap_inner
    self.run()
  File "/home/hzl/anaconda3/envs/django_web/lib/python3.8/threading.py", line 870, in run
    self._target(*self._args, **self._kwargs)
  File "/home/hzl/anaconda3/envs/django_web/lib/python3.8/site-packages/django/utils/autoreload.py", line 53, in wrapper
    fn(*args, **kwargs)
  File "/home/hzl/anaconda3/envs/django_web/lib/python3.8/site-packages/django/core/management/commands/runserver.py", line 109, in inner_run
    autoreload.raise_last_exception()
  File "/home/hzl/anaconda3/envs/django_web/lib/python3.8/site-packages/django/utils/autoreload.py", line 76, in raise_last_exception
    raise _exception[1]
  File "/home/hzl/anaconda3/envs/django_web/lib/python3.8/site-packages/django/core/management/__init__.py", line 357, in execute
    autoreload.check_errors(django.setup)()
  File "/home/hzl/anaconda3/envs/django_web/lib/python3.8/site-packages/django/utils/autoreload.py", line 53, in wrapper
    fn(*args, **kwargs)
  File "/home/hzl/anaconda3/envs/django_web/lib/python3.8/site-packages/django/__init__.py", line 24, in setup
    apps.populate(settings.INSTALLED_APPS)
  File "/home/hzl/anaconda3/envs/django_web/lib/python3.8/site-packages/django/apps/registry.py", line 114, in populate
    app_config.import_models()
  File "/home/hzl/anaconda3/envs/django_web/lib/python3.8/site-packages/django/apps/config.py", line 211, in import_models
    self.models_module = import_module(models_module_name)
  File "/home/hzl/anaconda3/envs/django_web/lib/python3.8/importlib/__init__.py", line 127, in import_module
    return _bootstrap._gcd_import(name[level:], package, level)
  File "<frozen importlib._bootstrap>", line 1014, in _gcd_import
  File "<frozen importlib._bootstrap>", line 991, in _find_and_load
  File "<frozen importlib._bootstrap>", line 975, in _find_and_load_unlocked
  File "<frozen importlib._bootstrap>", line 671, in _load_unlocked
  File "<frozen importlib._bootstrap_external>", line 779, in exec_module
  File "<frozen importlib._bootstrap_external>", line 916, in get_code
  File "<frozen importlib._bootstrap_external>", line 846, in source_to_code
  File "<frozen importlib._bootstrap>", line 219, in _call_with_frames_removed
  File "/home/hzl/django_web/myproject/boards/models.py", line 34
    return self.subject
                      ^
TabError: inconsistent use of tabs and spaces in indentation
Exception in thread django-main-thread:
Traceback (most recent call last):
  File "/home/hzl/anaconda3/envs/django_web/lib/python3.8/threading.py", line 932, in _bootstrap_inner
    self.run()
  File "/home/hzl/anaconda3/envs/django_web/lib/python3.8/threading.py", line 870, in run
    self._target(*self._args, **self._kwargs)
  File "/home/hzl/anaconda3/envs/django_web/lib/python3.8/site-packages/django/utils/autoreload.py", line 53, in wrapper
    fn(*args, **kwargs)
  File "/home/hzl/anaconda3/envs/django_web/lib/python3.8/site-packages/django/core/management/commands/runserver.py", line 117, in inner_run
    self.check(display_num_errors=True)
  File "/home/hzl/anaconda3/envs/django_web/lib/python3.8/site-packages/django/core/management/base.py", line 392, in check
    all_issues = self._run_checks(
  File "/home/hzl/anaconda3/envs/django_web/lib/python3.8/site-packages/django/core/management/base.py", line 382, in _run_checks
    return checks.run_checks(**kwargs)
  File "/home/hzl/anaconda3/envs/django_web/lib/python3.8/site-packages/django/core/checks/registry.py", line 72, in run_checks
    new_errors = check(app_configs=app_configs)
  File "/home/hzl/anaconda3/envs/django_web/lib/python3.8/site-packages/django/core/checks/urls.py", line 13, in check_url_config
    return check_resolver(resolver)
  File "/home/hzl/anaconda3/envs/django_web/lib/python3.8/site-packages/django/core/checks/urls.py", line 23, in check_resolver
    return check_method()
  File "/home/hzl/anaconda3/envs/django_web/lib/python3.8/site-packages/django/urls/resolvers.py", line 407, in check
    for pattern in self.url_patterns:
  File "/home/hzl/anaconda3/envs/django_web/lib/python3.8/site-packages/django/utils/functional.py", line 48, in __get__
    res = instance.__dict__[self.name] = self.func(instance)
  File "/home/hzl/anaconda3/envs/django_web/lib/python3.8/site-packages/django/urls/resolvers.py", line 588, in url_patterns
    patterns = getattr(self.urlconf_module, "urlpatterns", self.urlconf_module)
  File "/home/hzl/anaconda3/envs/django_web/lib/python3.8/site-packages/django/utils/functional.py", line 48, in __get__
    res = instance.__dict__[self.name] = self.func(instance)
  File "/home/hzl/anaconda3/envs/django_web/lib/python3.8/site-packages/django/urls/resolvers.py", line 581, in urlconf_module
    return import_module(self.urlconf_name)
  File "/home/hzl/anaconda3/envs/django_web/lib/python3.8/importlib/__init__.py", line 127, in import_module
    return _bootstrap._gcd_import(name[level:], package, level)
  File "<frozen importlib._bootstrap>", line 1014, in _gcd_import
  File "<frozen importlib._bootstrap>", line 991, in _find_and_load
  File "<frozen importlib._bootstrap>", line 975, in _find_and_load_unlocked
  File "<frozen importlib._bootstrap>", line 671, in _load_unlocked
  File "<frozen importlib._bootstrap_external>", line 783, in exec_module
  File "<frozen importlib._bootstrap>", line 219, in _call_with_frames_removed
  File "/home/hzl/django_web/myproject/myproject/urls.py", line 18, in <module>
    from boards import views
  File "/home/hzl/django_web/myproject/boards/views.py", line 8, in <module>
    from .forms import NewTopicForm, Userform, NewBlogForm
  File "/home/hzl/django_web/myproject/boards/forms.py", line 17, in <module>
    class NewBlogForm(forms.ModelForm):
  File "/home/hzl/django_web/myproject/boards/forms.py", line 24, in NewBlogForm
    class Meta:
  File "/home/hzl/django_web/myproject/boards/forms.py", line 25, in Meta
    model = Blog 
NameError: name 'Blog' is not defined
Exception in thread django-main-thread:
Traceback (most recent call last):
  File "/home/hzl/anaconda3/envs/django_web/lib/python3.8/threading.py", line 932, in _bootstrap_inner
    self.run()
  File "/home/hzl/anaconda3/envs/django_web/lib/python3.8/threading.py", line 870, in run
    self._target(*self._args, **self._kwargs)
  File "/home/hzl/anaconda3/envs/django_web/lib/python3.8/site-packages/django/utils/autoreload.py", line 53, in wrapper
    fn(*args, **kwargs)
  File "/home/hzl/anaconda3/envs/django_web/lib/python3.8/site-packages/django/core/management/commands/runserver.py", line 117, in inner_run
    self.check(display_num_errors=True)
  File "/home/hzl/anaconda3/envs/django_web/lib/python3.8/site-packages/django/core/management/base.py", line 392, in check
    all_issues = self._run_checks(
  File "/home/hzl/anaconda3/envs/django_web/lib/python3.8/site-packages/django/core/management/base.py", line 382, in _run_checks
    return checks.run_checks(**kwargs)
  File "/home/hzl/anaconda3/envs/django_web/lib/python3.8/site-packages/django/core/checks/registry.py", line 72, in run_checks
    new_errors = check(app_configs=app_configs)
  File "/home/hzl/anaconda3/envs/django_web/lib/python3.8/site-packages/django/core/checks/urls.py", line 13, in check_url_config
    return check_resolver(resolver)
  File "/home/hzl/anaconda3/envs/django_web/lib/python3.8/site-packages/django/core/checks/urls.py", line 23, in check_resolver
    return check_method()
  File "/home/hzl/anaconda3/envs/django_web/lib/python3.8/site-packages/django/urls/resolvers.py", line 407, in check
    for pattern in self.url_patterns:
  File "/home/hzl/anaconda3/envs/django_web/lib/python3.8/site-packages/django/utils/functional.py", line 48, in __get__
    res = instance.__dict__[self.name] = self.func(instance)
  File "/home/hzl/anaconda3/envs/django_web/lib/python3.8/site-packages/django/urls/resolvers.py", line 588, in url_patterns
    patterns = getattr(self.urlconf_module, "urlpatterns", self.urlconf_module)
  File "/home/hzl/anaconda3/envs/django_web/lib/python3.8/site-packages/django/utils/functional.py", line 48, in __get__
    res = instance.__dict__[self.name] = self.func(instance)
  File "/home/hzl/anaconda3/envs/django_web/lib/python3.8/site-packages/django/urls/resolvers.py", line 581, in urlconf_module
    return import_module(self.urlconf_name)
  File "/home/hzl/anaconda3/envs/django_web/lib/python3.8/importlib/__init__.py", line 127, in import_module
    return _bootstrap._gcd_import(name[level:], package, level)
  File "<frozen importlib._bootstrap>", line 1014, in _gcd_import
  File "<frozen importlib._bootstrap>", line 991, in _find_and_load
  File "<frozen importlib._bootstrap>", line 975, in _find_and_load_unlocked
  File "<frozen importlib._bootstrap>", line 671, in _load_unlocked
  File "<frozen importlib._bootstrap_external>", line 783, in exec_module
  File "<frozen importlib._bootstrap>", line 219, in _call_with_frames_removed
  File "/home/hzl/django_web/myproject/myproject/urls.py", line 18, in <module>
    from boards import views
  File "/home/hzl/django_web/myproject/boards/views.py", line 8, in <module>
    from .forms import NewTopicForm, Userform, NewBlogForm
  File "/home/hzl/django_web/myproject/boards/forms.py", line 17, in <module>
    class NewBlogForm(forms.ModelForm):
  File "/home/hzl/django_web/myproject/boards/forms.py", line 24, in NewBlogForm
    class Meta:
  File "/home/hzl/django_web/myproject/boards/forms.py", line 25, in Meta
    model = Blog 
NameError: name 'Blog' is not defined
Performing system checks...

Performing system checks...

[19/Jul/2020 09:15:48] "GET /blog HTTP/1.1" 200 4240
[19/Jul/2020 09:15:52] "GET / HTTP/1.1" 200 14939
[19/Jul/2020 09:15:53] "GET /blog HTTP/1.1" 200 4240
[19/Jul/2020 09:16:07] "GET / HTTP/1.1" 200 14939
[19/Jul/2020 09:16:17] "GET /blog HTTP/1.1" 200 4240
[19/Jul/2020 09:16:26] "GET / HTTP/1.1" 200 14939
[19/Jul/2020 09:16:27] "GET /blog HTTP/1.1" 200 4240
[19/Jul/2020 09:16:30] "GET / HTTP/1.1" 200 14939
Performing system checks...

System check identified no issues (0 silenced).
July 19, 2020 - 09:15:35
Django version 3.0.3, using settings 'myproject.settings'
Starting development server at http://0.0.0.0:8000/
Quit the server with CONTROL-C.
[08/Aug/2020 09:05:15] "GET /blog/ HTTP/1.1" 200 4101
[08/Aug/2020 09:05:21] "GET / HTTP/1.1" 200 15393
[08/Aug/2020 09:06:20] "GET / HTTP/1.1" 200 15393
[08/Aug/2020 09:06:34] "GET /blog/ HTTP/1.1" 200 4101
[08/Aug/2020 09:06:56] "GET /blog/new HTTP/1.1" 200 4690
[08/Aug/2020 09:06:59] "GET / HTTP/1.1" 200 15393
[08/Aug/2020 09:33:11] code 400, message Bad request syntax ('[\x00\x00\x00H\x00\x00\x00\x01\x10\x01\x00\x01\x04j\x00\x00\x01\x00\x00\x00\x00')
[08/Aug/2020 09:33:11] "[   H    j      " 400 -
[08/Aug/2020 12:12:55] "GET / HTTP/1.1" 200 14943
----------------------------------------
Exception happened during processing of request from ('89.248.174.166', 47534)
Traceback (most recent call last):
  File "/home/hzl/anaconda3/envs/django_web/lib/python3.8/socketserver.py", line 650, in process_request_thread
    self.finish_request(request, client_address)
  File "/home/hzl/anaconda3/envs/django_web/lib/python3.8/socketserver.py", line 360, in finish_request
    self.RequestHandlerClass(request, client_address, self)
  File "/home/hzl/anaconda3/envs/django_web/lib/python3.8/socketserver.py", line 720, in __init__
    self.handle()
  File "/home/hzl/anaconda3/envs/django_web/lib/python3.8/site-packages/django/core/servers/basehttp.py", line 174, in handle
    self.handle_one_request()
  File "/home/hzl/anaconda3/envs/django_web/lib/python3.8/site-packages/django/core/servers/basehttp.py", line 182, in handle_one_request
    self.raw_requestline = self.rfile.readline(65537)
  File "/home/hzl/anaconda3/envs/django_web/lib/python3.8/socket.py", line 669, in readinto
    return self._sock.recv_into(b)
ConnectionResetError: [Errno 104] Connection reset by peer
----------------------------------------
[08/Aug/2020 12:30:18] "GET / HTTP/1.0" 200 14943
[08/Aug/2020 12:30:18] "GET / HTTP/1.0" 200 14943
[08/Aug/2020 12:30:19] "GET / HTTP/1.1" 200 14943
[08/Aug/2020 12:30:19] "GET /favicon.ico HTTP/1.1" 404 179
[08/Aug/2020 12:48:52] "GET http://www.baidu.com/cache/global/img/gs.gif HTTP/1.1" 404 179
----------------------------------------
Exception happened during processing of request from ('80.82.70.187', 45987)
Traceback (most recent call last):
  File "/home/hzl/anaconda3/envs/django_web/lib/python3.8/socketserver.py", line 650, in process_request_thread
    self.finish_request(request, client_address)
  File "/home/hzl/anaconda3/envs/django_web/lib/python3.8/socketserver.py", line 360, in finish_request
    self.RequestHandlerClass(request, client_address, self)
  File "/home/hzl/anaconda3/envs/django_web/lib/python3.8/socketserver.py", line 720, in __init__
    self.handle()
  File "/home/hzl/anaconda3/envs/django_web/lib/python3.8/site-packages/django/core/servers/basehttp.py", line 174, in handle
    self.handle_one_request()
  File "/home/hzl/anaconda3/envs/django_web/lib/python3.8/site-packages/django/core/servers/basehttp.py", line 182, in handle_one_request
    self.raw_requestline = self.rfile.readline(65537)
  File "/home/hzl/anaconda3/envs/django_web/lib/python3.8/socket.py", line 669, in readinto
    return self._sock.recv_into(b)
ConnectionResetError: [Errno 104] Connection reset by peer
----------------------------------------
[08/Aug/2020 13:49:21] "GET / HTTP/1.0" 200 14943
[08/Aug/2020 16:04:19] "GET / HTTP/1.1" 200 14943
[08/Aug/2020 21:57:15] "GET / HTTP/1.1" 200 14943
----------------------------------------
Exception happened during processing of request from ('89.248.174.166', 41884)
Traceback (most recent call last):
  File "/home/hzl/anaconda3/envs/django_web/lib/python3.8/socketserver.py", line 650, in process_request_thread
    self.finish_request(request, client_address)
  File "/home/hzl/anaconda3/envs/django_web/lib/python3.8/socketserver.py", line 360, in finish_request
    self.RequestHandlerClass(request, client_address, self)
  File "/home/hzl/anaconda3/envs/django_web/lib/python3.8/socketserver.py", line 720, in __init__
    self.handle()
  File "/home/hzl/anaconda3/envs/django_web/lib/python3.8/site-packages/django/core/servers/basehttp.py", line 174, in handle
    self.handle_one_request()
  File "/home/hzl/anaconda3/envs/django_web/lib/python3.8/site-packages/django/core/servers/basehttp.py", line 182, in handle_one_request
    self.raw_requestline = self.rfile.readline(65537)
  File "/home/hzl/anaconda3/envs/django_web/lib/python3.8/socket.py", line 669, in readinto
    return self._sock.recv_into(b)
ConnectionResetError: [Errno 104] Connection reset by peer
----------------------------------------
[08/Aug/2020 22:27:51] "GET http://www.baidu.com/cache/global/img/gs.gif HTTP/1.1" 404 179
----------------------------------------
Exception happened during processing of request from ('80.82.70.187', 36862)
Traceback (most recent call last):
  File "/home/hzl/anaconda3/envs/django_web/lib/python3.8/socketserver.py", line 650, in process_request_thread
    self.finish_request(request, client_address)
  File "/home/hzl/anaconda3/envs/django_web/lib/python3.8/socketserver.py", line 360, in finish_request
    self.RequestHandlerClass(request, client_address, self)
  File "/home/hzl/anaconda3/envs/django_web/lib/python3.8/socketserver.py", line 720, in __init__
    self.handle()
  File "/home/hzl/anaconda3/envs/django_web/lib/python3.8/site-packages/django/core/servers/basehttp.py", line 174, in handle
    self.handle_one_request()
  File "/home/hzl/anaconda3/envs/django_web/lib/python3.8/site-packages/django/core/servers/basehttp.py", line 182, in handle_one_request
    self.raw_requestline = self.rfile.readline(65537)
  File "/home/hzl/anaconda3/envs/django_web/lib/python3.8/socket.py", line 669, in readinto
    return self._sock.recv_into(b)
ConnectionResetError: [Errno 104] Connection reset by peer
----------------------------------------
[08/Aug/2020 22:33:22] "HEAD / HTTP/1.0" 200 14943
[08/Aug/2020 23:22:10] "GET / HTTP/1.0" 200 14943
[09/Aug/2020 00:19:21] code 400, message Bad HTTP/0.9 request type ('\x03\x00\x00/*à\x00\x00\x00\x00\x00Cookie:')
[09/Aug/2020 00:19:21] "  /*à     Cookie: mstshash=Administr" 400 -
[09/Aug/2020 04:06:51] "GET /config/getuser?index=0 HTTP/1.1" 404 179
[09/Aug/2020 07:22:46] "GET / HTTP/1.1" 200 14943
[09/Aug/2020 07:22:47] "GET /static/css/app.css HTTP/1.1" 200 54
[09/Aug/2020 07:22:47] "GET /static/js/popper.min.js HTTP/1.1" 200 21257
[09/Aug/2020 07:22:48] "GET /static/js/jquery-3.4.1.min.js HTTP/1.1" 200 88145
[09/Aug/2020 07:22:49] "GET /static/css/bootstrap.css HTTP/1.1" 200 178159
[09/Aug/2020 07:22:49] "GET /static/js/bootstrap.js HTTP/1.1" 200 136323
[09/Aug/2020 07:22:51] "GET /favicon.ico HTTP/1.1" 404 179
[09/Aug/2020 07:22:58] "GET /blog/new HTTP/1.1" 302 0
[09/Aug/2020 07:22:58] "GET /login/?next=/blog/new HTTP/1.1" 200 2152
[09/Aug/2020 07:22:58] "GET /static/css/accounts.css HTTP/1.1" 200 201
[09/Aug/2020 07:22:58] "GET /static/css/img/circle-blues.png HTTP/1.1" 404 179
[09/Aug/2020 07:22:59] "GET /favicon.ico HTTP/1.1" 404 179
[09/Aug/2020 07:23:46] "GET /blog/new HTTP/1.1" 302 0
[09/Aug/2020 07:23:46] "GET /login/?next=/blog/new HTTP/1.1" 200 2152
[09/Aug/2020 07:23:46] "GET /static/css/img/circle-blues.png HTTP/1.1" 404 179
[09/Aug/2020 07:23:46] "GET /favicon.ico HTTP/1.1" 404 179
[09/Aug/2020 07:24:16] "GET /login/ HTTP/1.1" 200 2152
[09/Aug/2020 07:24:16] "GET /static/css/img/circle-blues.png HTTP/1.1" 404 179
[09/Aug/2020 07:24:16] "GET /favicon.ico HTTP/1.1" 404 179
[09/Aug/2020 07:24:43] "POST /login/ HTTP/1.1" 302 0
[09/Aug/2020 07:24:43] "GET / HTTP/1.1" 200 15393
[09/Aug/2020 07:24:44] "GET /favicon.ico HTTP/1.1" 404 179
[09/Aug/2020 07:24:46] "GET /blog/new HTTP/1.1" 200 4690
[09/Aug/2020 07:24:47] "GET /favicon.ico HTTP/1.1" 404 179
[09/Aug/2020 07:24:59] "POST /blog/new HTTP/1.1" 500 145
[09/Aug/2020 07:25:00] "GET /favicon.ico HTTP/1.1" 404 179
[09/Aug/2020 07:25:04] "GET /blog/new HTTP/1.1" 200 4690
[09/Aug/2020 07:25:04] "GET /favicon.ico HTTP/1.1" 404 179
[09/Aug/2020 07:25:06] "GET / HTTP/1.1" 200 15393
[09/Aug/2020 07:25:06] "GET /favicon.ico HTTP/1.1" 404 179
[09/Aug/2020 07:25:31] "GET /blog HTTP/1.1" 301 0
[09/Aug/2020 07:25:31] "GET /blog/ HTTP/1.1" 200 4101
[09/Aug/2020 07:25:33] "GET /favicon.ico HTTP/1.1" 404 179
[09/Aug/2020 07:25:55] "GET /blog/new HTTP/1.1" 200 4690
[09/Aug/2020 07:25:57] "GET /favicon.ico HTTP/1.1" 404 179
[09/Aug/2020 07:26:06] "GET /blog/ HTTP/1.1" 200 4101
[09/Aug/2020 07:26:07] "GET /favicon.ico HTTP/1.1" 404 179
[09/Aug/2020 07:26:10] "GET / HTTP/1.1" 200 15393
[09/Aug/2020 07:26:10] "GET /favicon.ico HTTP/1.1" 404 179
[09/Aug/2020 07:27:23] "GET /? HTTP/1.1" 200 15393
[09/Aug/2020 07:27:24] "GET /favicon.ico HTTP/1.1" 404 179
[09/Aug/2020 07:27:27] "GET /? HTTP/1.1" 200 15393
----------------------------------------
Exception happened during processing of request from ('223.104.20.49', 17811)
Traceback (most recent call last):
  File "/home/hzl/anaconda3/envs/django_web/lib/python3.8/socketserver.py", line 650, in process_request_thread
    self.finish_request(request, client_address)
  File "/home/hzl/anaconda3/envs/django_web/lib/python3.8/socketserver.py", line 360, in finish_request
    self.RequestHandlerClass(request, client_address, self)
  File "/home/hzl/anaconda3/envs/django_web/lib/python3.8/socketserver.py", line 720, in __init__
    self.handle()
  File "/home/hzl/anaconda3/envs/django_web/lib/python3.8/site-packages/django/core/servers/basehttp.py", line 174, in handle
    self.handle_one_request()
  File "/home/hzl/anaconda3/envs/django_web/lib/python3.8/site-packages/django/core/servers/basehttp.py", line 182, in handle_one_request
    self.raw_requestline = self.rfile.readline(65537)
  File "/home/hzl/anaconda3/envs/django_web/lib/python3.8/socket.py", line 669, in readinto
    return self._sock.recv_into(b)
ConnectionResetError: [Errno 104] Connection reset by peer
----------------------------------------
----------------------------------------
Exception happened during processing of request from ('223.104.20.49', 17813)
Traceback (most recent call last):
  File "/home/hzl/anaconda3/envs/django_web/lib/python3.8/socketserver.py", line 650, in process_request_thread
    self.finish_request(request, client_address)
  File "/home/hzl/anaconda3/envs/django_web/lib/python3.8/socketserver.py", line 360, in finish_request
    self.RequestHandlerClass(request, client_address, self)
  File "/home/hzl/anaconda3/envs/django_web/lib/python3.8/socketserver.py", line 720, in __init__
    self.handle()
  File "/home/hzl/anaconda3/envs/django_web/lib/python3.8/site-packages/django/core/servers/basehttp.py", line 174, in handle
    self.handle_one_request()
  File "/home/hzl/anaconda3/envs/django_web/lib/python3.8/site-packages/django/core/servers/basehttp.py", line 182, in handle_one_request
    self.raw_requestline = self.rfile.readline(65537)
  File "/home/hzl/anaconda3/envs/django_web/lib/python3.8/socket.py", line 669, in readinto
    return self._sock.recv_into(b)
ConnectionResetError: [Errno 104] Connection reset by peer
----------------------------------------
----------------------------------------
Exception happened during processing of request from ('223.104.20.49', 17812)
Traceback (most recent call last):
  File "/home/hzl/anaconda3/envs/django_web/lib/python3.8/socketserver.py", line 650, in process_request_thread
    self.finish_request(request, client_address)
  File "/home/hzl/anaconda3/envs/django_web/lib/python3.8/socketserver.py", line 360, in finish_request
    self.RequestHandlerClass(request, client_address, self)
  File "/home/hzl/anaconda3/envs/django_web/lib/python3.8/socketserver.py", line 720, in __init__
    self.handle()
  File "/home/hzl/anaconda3/envs/django_web/lib/python3.8/site-packages/django/core/servers/basehttp.py", line 174, in handle
    self.handle_one_request()
  File "/home/hzl/anaconda3/envs/django_web/lib/python3.8/site-packages/django/core/servers/basehttp.py", line 182, in handle_one_request
    self.raw_requestline = self.rfile.readline(65537)
  File "/home/hzl/anaconda3/envs/django_web/lib/python3.8/socket.py", line 669, in readinto
    return self._sock.recv_into(b)
ConnectionResetError: [Errno 104] Connection reset by peer
----------------------------------------
----------------------------------------
Exception happened during processing of request from ('223.104.20.49', 17810)
Traceback (most recent call last):
  File "/home/hzl/anaconda3/envs/django_web/lib/python3.8/socketserver.py", line 650, in process_request_thread
    self.finish_request(request, client_address)
  File "/home/hzl/anaconda3/envs/django_web/lib/python3.8/socketserver.py", line 360, in finish_request
    self.RequestHandlerClass(request, client_address, self)
  File "/home/hzl/anaconda3/envs/django_web/lib/python3.8/socketserver.py", line 720, in __init__
    self.handle()
  File "/home/hzl/anaconda3/envs/django_web/lib/python3.8/site-packages/django/core/servers/basehttp.py", line 174, in handle
    self.handle_one_request()
  File "/home/hzl/anaconda3/envs/django_web/lib/python3.8/site-packages/django/core/servers/basehttp.py", line 182, in handle_one_request
    self.raw_requestline = self.rfile.readline(65537)
  File "/home/hzl/anaconda3/envs/django_web/lib/python3.8/socket.py", line 669, in readinto
    return self._sock.recv_into(b)
ConnectionResetError: [Errno 104] Connection reset by peer
----------------------------------------
----------------------------------------
Exception happened during processing of request from ('223.104.20.49', 17809)
Traceback (most recent call last):
  File "/home/hzl/anaconda3/envs/django_web/lib/python3.8/socketserver.py", line 650, in process_request_thread
    self.finish_request(request, client_address)
  File "/home/hzl/anaconda3/envs/django_web/lib/python3.8/socketserver.py", line 360, in finish_request
    self.RequestHandlerClass(request, client_address, self)
  File "/home/hzl/anaconda3/envs/django_web/lib/python3.8/socketserver.py", line 720, in __init__
    self.handle()
  File "/home/hzl/anaconda3/envs/django_web/lib/python3.8/site-packages/django/core/servers/basehttp.py", line 174, in handle
    self.handle_one_request()
  File "/home/hzl/anaconda3/envs/django_web/lib/python3.8/site-packages/django/core/servers/basehttp.py", line 182, in handle_one_request
    self.raw_requestline = self.rfile.readline(65537)
  File "/home/hzl/anaconda3/envs/django_web/lib/python3.8/socket.py", line 669, in readinto
    return self._sock.recv_into(b)
ConnectionResetError: [Errno 104] Connection reset by peer
----------------------------------------
[09/Aug/2020 07:34:43] "GET http://119.45.46.117:8000/blog HTTP/1.1" 404 179
----------------------------------------
Exception happened during processing of request from ('58.247.212.239', 34044)
Traceback (most recent call last):
  File "/home/hzl/anaconda3/envs/django_web/lib/python3.8/socketserver.py", line 650, in process_request_thread
    self.finish_request(request, client_address)
  File "/home/hzl/anaconda3/envs/django_web/lib/python3.8/socketserver.py", line 360, in finish_request
    self.RequestHandlerClass(request, client_address, self)
  File "/home/hzl/anaconda3/envs/django_web/lib/python3.8/socketserver.py", line 720, in __init__
    self.handle()
  File "/home/hzl/anaconda3/envs/django_web/lib/python3.8/site-packages/django/core/servers/basehttp.py", line 174, in handle
    self.handle_one_request()
  File "/home/hzl/anaconda3/envs/django_web/lib/python3.8/site-packages/django/core/servers/basehttp.py", line 182, in handle_one_request
    self.raw_requestline = self.rfile.readline(65537)
  File "/home/hzl/anaconda3/envs/django_web/lib/python3.8/socket.py", line 669, in readinto
    return self._sock.recv_into(b)
ConnectionResetError: [Errno 104] Connection reset by peer
----------------------------------------
[09/Aug/2020 07:44:29] "GET / HTTP/1.1" 200 14943
[09/Aug/2020 07:44:29] "GET /static/css/app.css HTTP/1.1" 200 54
[09/Aug/2020 07:44:29] "GET /static/js/popper.min.js HTTP/1.1" 200 21257
[09/Aug/2020 07:44:29] "GET /static/css/bootstrap.css HTTP/1.1" 200 178159
[09/Aug/2020 07:44:31] "GET /static/js/bootstrap.js HTTP/1.1" 200 136323
[09/Aug/2020 07:44:31] "GET /static/js/jquery-3.4.1.min.js HTTP/1.1" 200 88145
[09/Aug/2020 07:44:32] "GET /favicon.ico HTTP/1.1" 404 179
[09/Aug/2020 07:47:11] "GET / HTTP/1.1" 200 14943
Performing system checks...

System check identified no issues (0 silenced).
August 08, 2020 - 09:05:06
Django version 3.0.3, using settings 'myproject.settings'
Starting development server at http://0.0.0.0:8000/
Quit the server with CONTROL-C.
